2023-08-24 14:14:24,915 INFO    MainThread:3610 [wandb_setup.py:_flush():76] Current SDK version is 0.15.8
2023-08-24 14:14:24,915 INFO    MainThread:3610 [wandb_setup.py:_flush():76] Configure stats pid to 3610
2023-08-24 14:14:24,916 INFO    MainThread:3610 [wandb_setup.py:_flush():76] Loading settings from /Users/gabdu45/.config/wandb/settings
2023-08-24 14:14:24,916 INFO    MainThread:3610 [wandb_setup.py:_flush():76] Loading settings from /Users/gabdu45/PycharmProjects/segmentationCryoEM/wandb/settings
2023-08-24 14:14:24,916 INFO    MainThread:3610 [wandb_setup.py:_flush():76] Loading settings from environment variables: {}
2023-08-24 14:14:24,916 INFO    MainThread:3610 [wandb_setup.py:_flush():76] Inferring run settings from compute environment: {'program_relpath': 'main.py', 'program': '/Users/gabdu45/PycharmProjects/segmentationCryoEM/main.py'}
2023-08-24 14:14:24,916 INFO    MainThread:3610 [wandb_init.py:_log_setup():507] Logging user logs to /Users/gabdu45/PycharmProjects/segmentationCryoEM/wandb/run-20230824_141424-fhz93olj/logs/debug.log
2023-08-24 14:14:24,916 INFO    MainThread:3610 [wandb_init.py:_log_setup():508] Logging internal logs to /Users/gabdu45/PycharmProjects/segmentationCryoEM/wandb/run-20230824_141424-fhz93olj/logs/debug-internal.log
2023-08-24 14:14:24,916 INFO    MainThread:3610 [wandb_init.py:init():547] calling init triggers
2023-08-24 14:14:24,916 INFO    MainThread:3610 [wandb_init.py:init():554] wandb.init called with sweep_config: {}
config: {'learning_rate': 0.0001}
2023-08-24 14:14:24,916 INFO    MainThread:3610 [wandb_init.py:init():596] starting backend
2023-08-24 14:14:24,916 INFO    MainThread:3610 [wandb_init.py:init():600] setting up manager
2023-08-24 14:14:24,924 INFO    MainThread:3610 [backend.py:_multiprocessing_setup():106] multiprocessing start_methods=spawn,fork,forkserver, using: spawn
2023-08-24 14:14:24,927 INFO    MainThread:3610 [wandb_init.py:init():606] backend started and connected
2023-08-24 14:14:24,933 INFO    MainThread:3610 [wandb_init.py:init():697] updated telemetry
2023-08-24 14:14:24,987 INFO    MainThread:3610 [wandb_init.py:init():730] communicating run to backend with 60.0 second timeout
2023-08-24 14:14:53,437 INFO    Thread-1 (wrapped_target):3610 [retry.py:__call__():172] Retry attempt failed:
Traceback (most recent call last):
  File "/Users/gabdu45/.local/lib/python3.10/site-packages/urllib3/connection.py", line 174, in _new_conn
    conn = connection.create_connection(
  File "/Users/gabdu45/.local/lib/python3.10/site-packages/urllib3/util/connection.py", line 95, in create_connection
    raise err
  File "/Users/gabdu45/.local/lib/python3.10/site-packages/urllib3/util/connection.py", line 85, in create_connection
    sock.connect(sa)
TimeoutError: timed out

During handling of the above exception, another exception occurred:

Traceback (most recent call last):
  File "/Users/gabdu45/.local/lib/python3.10/site-packages/urllib3/connectionpool.py", line 703, in urlopen
    httplib_response = self._make_request(
  File "/Users/gabdu45/.local/lib/python3.10/site-packages/urllib3/connectionpool.py", line 386, in _make_request
    self._validate_conn(conn)
  File "/Users/gabdu45/.local/lib/python3.10/site-packages/urllib3/connectionpool.py", line 1042, in _validate_conn
    conn.connect()
  File "/Users/gabdu45/.local/lib/python3.10/site-packages/urllib3/connection.py", line 358, in connect
    self.sock = conn = self._new_conn()
  File "/Users/gabdu45/.local/lib/python3.10/site-packages/urllib3/connection.py", line 179, in _new_conn
    raise ConnectTimeoutError(
urllib3.exceptions.ConnectTimeoutError: (<urllib3.connection.HTTPSConnection object at 0x7f78b0019990>, 'Connection to api.wandb.ai timed out. (connect timeout=10)')

During handling of the above exception, another exception occurred:

Traceback (most recent call last):
  File "/Users/gabdu45/.local/lib/python3.10/site-packages/requests/adapters.py", line 489, in send
    resp = conn.urlopen(
  File "/Users/gabdu45/.local/lib/python3.10/site-packages/urllib3/connectionpool.py", line 787, in urlopen
    retries = retries.increment(
  File "/Users/gabdu45/.local/lib/python3.10/site-packages/urllib3/util/retry.py", line 592, in increment
    raise MaxRetryError(_pool, url, error or ResponseError(cause))
urllib3.exceptions.MaxRetryError: HTTPSConnectionPool(host='api.wandb.ai', port=443): Max retries exceeded with url: /graphql (Caused by ConnectTimeoutError(<urllib3.connection.HTTPSConnection object at 0x7f78b0019990>, 'Connection to api.wandb.ai timed out. (connect timeout=10)'))

During handling of the above exception, another exception occurred:

Traceback (most recent call last):
  File "/Users/gabdu45/.local/lib/python3.10/site-packages/wandb/sdk/lib/retry.py", line 131, in __call__
    result = self._call_fn(*args, **kwargs)
  File "/Users/gabdu45/.local/lib/python3.10/site-packages/wandb/sdk/internal/internal_api.py", line 323, in execute
    return self.client.execute(*args, **kwargs)  # type: ignore
  File "/Users/gabdu45/.local/lib/python3.10/site-packages/wandb/vendor/gql-0.2.0/wandb_gql/client.py", line 52, in execute
    result = self._get_result(document, *args, **kwargs)
  File "/Users/gabdu45/.local/lib/python3.10/site-packages/wandb/vendor/gql-0.2.0/wandb_gql/client.py", line 60, in _get_result
    return self.transport.execute(document, *args, **kwargs)
  File "/Users/gabdu45/.local/lib/python3.10/site-packages/wandb/sdk/lib/gql_request.py", line 55, in execute
    request = self.session.post(self.url, **post_args)
  File "/Users/gabdu45/.local/lib/python3.10/site-packages/requests/sessions.py", line 635, in post
    return self.request("POST", url, data=data, json=json, **kwargs)
  File "/Users/gabdu45/.local/lib/python3.10/site-packages/requests/sessions.py", line 587, in request
    resp = self.send(prep, **send_kwargs)
  File "/Users/gabdu45/.local/lib/python3.10/site-packages/requests/sessions.py", line 701, in send
    r = adapter.send(request, **kwargs)
  File "/Users/gabdu45/.local/lib/python3.10/site-packages/requests/adapters.py", line 553, in send
    raise ConnectTimeout(e, request=request)
requests.exceptions.ConnectTimeout: HTTPSConnectionPool(host='api.wandb.ai', port=443): Max retries exceeded with url: /graphql (Caused by ConnectTimeoutError(<urllib3.connection.HTTPSConnection object at 0x7f78b0019990>, 'Connection to api.wandb.ai timed out. (connect timeout=10)'))
2023-08-24 14:15:25,296 ERROR   MainThread:3610 [wandb_init.py:init():756] encountered error: Run initialization has timed out after 60.0 sec. 
Please refer to the documentation for additional information: https://docs.wandb.ai/guides/track/tracking-faq#initstarterror-error-communicating-with-wandb-process-
2023-08-24 14:15:27,347 ERROR   MainThread:3610 [wandb_init.py:init():1165] Run initialization has timed out after 60.0 sec. 
Please refer to the documentation for additional information: https://docs.wandb.ai/guides/track/tracking-faq#initstarterror-error-communicating-with-wandb-process-
Traceback (most recent call last):
  File "/Users/gabdu45/.local/lib/python3.10/site-packages/wandb/sdk/wandb_init.py", line 1147, in init
    run = wi.init()
  File "/Users/gabdu45/.local/lib/python3.10/site-packages/wandb/sdk/wandb_init.py", line 762, in init
    raise error
wandb.errors.CommError: Run initialization has timed out after 60.0 sec. 
Please refer to the documentation for additional information: https://docs.wandb.ai/guides/track/tracking-faq#initstarterror-error-communicating-with-wandb-process-
2023-08-24 14:15:30,328 WARNING MsgRouterThr:3610 [router.py:message_loop():77] message_loop has been closed
