2023-08-24 14:14:24,928 INFO    StreamThr :3622 [internal.py:wandb_internal():86] W&B internal server running at pid: 3622, started at: 2023-08-24 14:14:24.927841
2023-08-24 14:14:24,930 DEBUG   HandlerThread:3622 [handler.py:handle_request():144] handle_request: status
2023-08-24 14:14:24,935 INFO    WriterThread:3622 [datastore.py:open_for_write():85] open: /Users/gabdu45/PycharmProjects/segmentationCryoEM/wandb/run-20230824_141424-fhz93olj/run-fhz93olj.wandb
2023-08-24 14:14:24,935 DEBUG   SenderThread:3622 [sender.py:send():379] send: header
2023-08-24 14:14:24,989 DEBUG   SenderThread:3622 [sender.py:send():379] send: run
2023-08-24 14:14:30,014 DEBUG   HandlerThread:3622 [handler.py:handle_request():144] handle_request: keepalive
2023-08-24 14:14:35,038 DEBUG   HandlerThread:3622 [handler.py:handle_request():144] handle_request: keepalive
2023-08-24 14:14:40,059 DEBUG   HandlerThread:3622 [handler.py:handle_request():144] handle_request: keepalive
2023-08-24 14:14:45,088 DEBUG   HandlerThread:3622 [handler.py:handle_request():144] handle_request: keepalive
2023-08-24 14:14:46,358 INFO    SenderThread:3622 [retry.py:__call__():172] Retry attempt failed:
Traceback (most recent call last):
  File "/Users/gabdu45/.local/lib/python3.10/site-packages/urllib3/connection.py", line 174, in _new_conn
    conn = connection.create_connection(
  File "/Users/gabdu45/.local/lib/python3.10/site-packages/urllib3/util/connection.py", line 95, in create_connection
    raise err
  File "/Users/gabdu45/.local/lib/python3.10/site-packages/urllib3/util/connection.py", line 85, in create_connection
    sock.connect(sa)
OSError: [Errno 51] Network is unreachable

During handling of the above exception, another exception occurred:

Traceback (most recent call last):
  File "/Users/gabdu45/.local/lib/python3.10/site-packages/urllib3/connectionpool.py", line 703, in urlopen
    httplib_response = self._make_request(
  File "/Users/gabdu45/.local/lib/python3.10/site-packages/urllib3/connectionpool.py", line 386, in _make_request
    self._validate_conn(conn)
  File "/Users/gabdu45/.local/lib/python3.10/site-packages/urllib3/connectionpool.py", line 1042, in _validate_conn
    conn.connect()
  File "/Users/gabdu45/.local/lib/python3.10/site-packages/urllib3/connection.py", line 358, in connect
    self.sock = conn = self._new_conn()
  File "/Users/gabdu45/.local/lib/python3.10/site-packages/urllib3/connection.py", line 186, in _new_conn
    raise NewConnectionError(
urllib3.exceptions.NewConnectionError: <urllib3.connection.HTTPSConnection object at 0x7fd9a31f83d0>: Failed to establish a new connection: [Errno 51] Network is unreachable

During handling of the above exception, another exception occurred:

Traceback (most recent call last):
  File "/Users/gabdu45/.local/lib/python3.10/site-packages/requests/adapters.py", line 489, in send
    resp = conn.urlopen(
  File "/Users/gabdu45/.local/lib/python3.10/site-packages/urllib3/connectionpool.py", line 787, in urlopen
    retries = retries.increment(
  File "/Users/gabdu45/.local/lib/python3.10/site-packages/urllib3/util/retry.py", line 592, in increment
    raise MaxRetryError(_pool, url, error or ResponseError(cause))
urllib3.exceptions.MaxRetryError: HTTPSConnectionPool(host='api.wandb.ai', port=443): Max retries exceeded with url: /graphql (Caused by NewConnectionError('<urllib3.connection.HTTPSConnection object at 0x7fd9a31f83d0>: Failed to establish a new connection: [Errno 51] Network is unreachable'))

During handling of the above exception, another exception occurred:

Traceback (most recent call last):
  File "/Users/gabdu45/.local/lib/python3.10/site-packages/wandb/sdk/lib/retry.py", line 131, in __call__
    result = self._call_fn(*args, **kwargs)
  File "/Users/gabdu45/.local/lib/python3.10/site-packages/wandb/sdk/internal/internal_api.py", line 323, in execute
    return self.client.execute(*args, **kwargs)  # type: ignore
  File "/Users/gabdu45/.local/lib/python3.10/site-packages/wandb/vendor/gql-0.2.0/wandb_gql/client.py", line 52, in execute
    result = self._get_result(document, *args, **kwargs)
  File "/Users/gabdu45/.local/lib/python3.10/site-packages/wandb/vendor/gql-0.2.0/wandb_gql/client.py", line 60, in _get_result
    return self.transport.execute(document, *args, **kwargs)
  File "/Users/gabdu45/.local/lib/python3.10/site-packages/wandb/sdk/lib/gql_request.py", line 55, in execute
    request = self.session.post(self.url, **post_args)
  File "/Users/gabdu45/.local/lib/python3.10/site-packages/requests/sessions.py", line 635, in post
    return self.request("POST", url, data=data, json=json, **kwargs)
  File "/Users/gabdu45/.local/lib/python3.10/site-packages/requests/sessions.py", line 587, in request
    resp = self.send(prep, **send_kwargs)
  File "/Users/gabdu45/.local/lib/python3.10/site-packages/requests/sessions.py", line 701, in send
    r = adapter.send(request, **kwargs)
  File "/Users/gabdu45/.local/lib/python3.10/site-packages/requests/adapters.py", line 565, in send
    raise ConnectionError(e, request=request)
requests.exceptions.ConnectionError: HTTPSConnectionPool(host='api.wandb.ai', port=443): Max retries exceeded with url: /graphql (Caused by NewConnectionError('<urllib3.connection.HTTPSConnection object at 0x7fd9a31f83d0>: Failed to establish a new connection: [Errno 51] Network is unreachable'))
2023-08-24 14:14:50,111 DEBUG   HandlerThread:3622 [handler.py:handle_request():144] handle_request: keepalive
2023-08-24 14:14:55,136 DEBUG   HandlerThread:3622 [handler.py:handle_request():144] handle_request: keepalive
2023-08-24 14:15:00,159 DEBUG   HandlerThread:3622 [handler.py:handle_request():144] handle_request: keepalive
2023-08-24 14:15:05,187 DEBUG   HandlerThread:3622 [handler.py:handle_request():144] handle_request: keepalive
2023-08-24 14:15:10,210 DEBUG   HandlerThread:3622 [handler.py:handle_request():144] handle_request: keepalive
2023-08-24 14:15:15,235 DEBUG   HandlerThread:3622 [handler.py:handle_request():144] handle_request: keepalive
2023-08-24 14:15:20,268 DEBUG   HandlerThread:3622 [handler.py:handle_request():144] handle_request: keepalive
2023-08-24 14:15:25,297 DEBUG   HandlerThread:3622 [handler.py:handle_request():144] handle_request: cancel
2023-08-24 14:15:25,297 DEBUG   HandlerThread:3622 [handler.py:handle_request():144] handle_request: cancel
2023-08-24 14:15:25,298 DEBUG   SenderThread:3622 [sender.py:send():388] Record cancelled: run
2023-08-24 14:15:25,299 DEBUG   HandlerThread:3622 [handler.py:handle_request():144] handle_request: status_report
2023-08-24 14:15:27,354 DEBUG   HandlerThread:3622 [handler.py:handle_request():144] handle_request: shutdown
2023-08-24 14:15:27,355 INFO    HandlerThread:3622 [handler.py:finish():857] shutting down handler
2023-08-24 14:15:28,311 INFO    SenderThread:3622 [sender.py:finish():1552] shutting down sender
2023-08-24 14:15:28,311 INFO    WriterThread:3622 [datastore.py:close():294] close: /Users/gabdu45/PycharmProjects/segmentationCryoEM/wandb/run-20230824_141424-fhz93olj/run-fhz93olj.wandb
